Workbook

Sheet README
A1: 101 Okey — Development Plan & Task Tracker
A3: How to use this workbook
A4: 1) Go to Settings: set Project Start Date, and optionally edit the dropdown lists. 2) Go to Tasks: this is the master backlog. Filter by Stage/Status/Priority and feed tasks to Codex. 3) Use the Notes / Codex Prompt Seed column as the starting prompt when delegating a task. 4) Go to Dashboard for progress charts; Gantt for the stage timeline. Workflow suggestion: - Keep tasks in Backlog until you’re ready; then set Status=Planned and assign a Start Offset. - When you start coding, set Status=In Progress. Use Blocked when waiting on dependencies. - Mark Done only when Acceptance Criteria is met on both PC and Android (when applicable). Online multiplayer is planned using Epic Online Services (EOS) P2P with guest (DeviceID) login by default. Some networks can still fail; we also keep LAN/direct-connect as a fallback mode.

Sheet Settings
A1: Project Settings
A3: Project Name | B3: 101 Okey (Godot)
A4: Project Start Date | B4: 46056
A5: Sprint Length (days) | B5: 14
A6: Default Turn Timer (sec) | B6: 60
A7: Default Match Mode | B7: Target Score
A8: Default Target Score | B8: 101
A9: Default Rounds | B9: 8
A10: Animation Speed | B10: Normal
A11: Tips Verbosity | B11: OnboardingOnly
A12: Online Identity | B12: GuestDeviceID
A13: Dropdown Lists (edit if needed)
A14: Status | B14: Priority | C14: Type | D14: Platform | E14: Owner | F14: Stage | G14: Bot Personality | H14: Difficulty
A15: Backlog | B15: P0 | C15: Design | D15: All | E15: You | F15: 0 - Preproduction (Spec & Design Lock) | G15: Random | H15: Easy
A16: Planned | B16: P1 | C16: Engineering | D16: Offline | E16: Codex | F16: 1 - Project Setup & Tooling | G16: Aggressive | H16: Medium
A17: In Progress | B17: P2 | C17: Art | D17: Online | E17: You+Codex | F17: 2 - Core Game Engine (Rules/State) | G17: Conservative | H17: Hard
A18: Blocked | C18: Audio | D18: PC | E18: TBD | F18: 3 - Offline Gameplay Loop | G18: Chaotic
A19: Review | C19: QA | D19: Android | F19: 4 - UI/UX & Input
A20: Done | C20: DevOps | F20: 5 - Bots (AI)
C21: Writing | F21: 6 - Online Multiplayer (EOS + P2P)
F22: 7 - Reconnect & Resilience
F23: 8 - Polish (Audio/Accessibility/Perf)
F24: 9 - QA & Test Matrix
F25: 10 - Builds & Release Pipeline
F26: 11 - Store/Distribution Prep

Sheet Tasks
A1: ID | B1: Epic | C1: Feature | D1: Task | E1: Description | F1: Stage | G1: Type | H1: Platform | I1: Priority | J1: Est (hrs) | K1: Est (days) | L1: Dependencies | M1: Owner | N1: Status | O1: Start Offset (d) | P1: Start Date | Q1: End Date | R1: Notes / Codex Prompt Seed | S1: Acceptance Criteria
A2: T-0001 | B2: Preproduction | C2: Ruleset | D2: Write Classic TR 101 rules specification | E2: Document full TR 101 Okey rules: tiles, indicator/okey, dealing, turns, opening, scoring, end-of-round, penalties. | F2: 0 - Preproduction (Spec & Design Lock) | G2: Design | H2: All | I2: P0 | J2: 10 | K2: 2 | M2: You+Codex | N2: Backlog | O2: 0 | P2: =Settings!$B$4+O2 -> 46056 | Q2: =P2+ROUNDUP(K2,0)-1 -> 46057 | R2: Ask Codex to draft a rules spec doc based on Turkish 101 Okey; verify manually. | S2: A single source-of-truth rules spec exists and is reviewed; ambiguous points resolved.
A3: T-0002 | B3: Preproduction | C3: Ruleset | D3: Define house-rule toggles + presets list | E3: Decide safe modular toggles (timer, match target, opening threshold, scoring multipliers) and 3-5 presets. | F3: 0 - Preproduction (Spec & Design Lock) | G3: Design | H3: All | I3: P0 | J3: 6 | K3: 1 | M3: You+Codex | N3: Backlog | O3: 1 | P3: =Settings!$B$4+O3 -> 46057 | Q3: =P3+ROUNDUP(K3,0)-1 -> 46057 | S3: RuleConfig v1 list finalized; no toggle changes core tile mechanics.
A4: T-0003 | B4: Preproduction | C4: Architecture | D4: Define GameState schema + action API | E4: Define data model (Tile, PlayerState, GameState) + all legal actions with payloads. | F4: 0 - Preproduction (Spec & Design Lock) | G4: Design | H4: All | I4: P0 | J4: 8 | K4: 2 | M4: You+Codex | N4: Backlog | O4: 1 | P4: =Settings!$B$4+O4 -> 46057 | Q4: =P4+ROUNDUP(K4,0)-1 -> 46058 | S4: Action list covers all gameplay; each action maps to validation + apply.
A5: T-0004 | B5: Preproduction | C5: Architecture | D5: Networking event flow (host-authoritative) | E5: Define online flow: host validates intents, broadcasts deltas, resync snapshots, reconnect, AI takeover. | F5: 0 - Preproduction (Spec & Design Lock) | G5: Design | H5: Online | I5: P0 | J5: 6 | K5: 1 | M5: You+Codex | N5: Backlog | O5: 2 | P5: =Settings!$B$4+O5 -> 46058 | Q5: =P5+ROUNDUP(K5,0)-1 -> 46058 | S5: Sequence diagrams for normal play + reconnect; no undefined states.
A6: T-0005 | B6: Preproduction | C6: UX | D6: Wireframe core screens | E6: Wireframe: Main Menu, Offline Setup, Online Lobby, Table, Round Summary, Settings. | F6: 0 - Preproduction (Spec & Design Lock) | G6: Design | H6: All | I6: P0 | J6: 8 | K6: 2 | M6: You+Codex | N6: Backlog | O6: 2 | P6: =Settings!$B$4+O6 -> 46058 | Q6: =P6+ROUNDUP(K6,0)-1 -> 46059 | S6: Wireframes cover all actions; Android landscape considered.
A7: T-0006 | B7: Preproduction | C7: Art | D7: Visual style mini moodboard | E7: Pick flat 2D style references for tiles/table; define fonts, spacing, color palette, icon style. | F7: 0 - Preproduction (Spec & Design Lock) | G7: Design | H7: All | I7: P1 | J7: 4 | K7: 1 | M7: You+Codex | N7: Backlog | O7: 3 | P7: =Settings!$B$4+O7 -> 46059 | Q7: =P7+ROUNDUP(K7,0)-1 -> 46059 | S7: Style guide page with tile mock + UI colors.
A8: T-0007 | B8: Preproduction | C8: Backlog | D8: Create task board + definitions | E8: Define status workflow, priority rules, definition of done, branching strategy. | F8: 0 - Preproduction (Spec & Design Lock) | G8: Design | H8: All | I8: P1 | J8: 3 | K8: 1 | M8: You+Codex | N8: Backlog | O8: 3 | P8: =Settings!$B$4+O8 -> 46059 | Q8: =P8+ROUNDUP(K8,0)-1 -> 46059 | S8: Workflow documented; tasks ready for execution.
A9: T-0008 | B9: Setup | C9: Repo | D9: Initialize repository + .gitignore + LFS (if needed) | E9: Create repo, ignore Godot artifacts, decide if LFS needed for art. | F9: 1 - Project Setup & Tooling | G9: DevOps | H9: All | I9: P0 | J9: 2 | K9: 0.5 | M9: You+Codex | N9: Backlog | O9: 4 | P9: =Settings!$B$4+O9 -> 46060 | Q9: =P9+ROUNDUP(K9,0)-1 -> 46060 | S9: Repo exists; clean status after opening project.
A10: T-0009 | B10: Setup | C10: Godot | D10: Create Godot 4 project structure | E10: Setup scenes, scripts, autoloads folders, naming conventions. | F10: 1 - Project Setup & Tooling | G10: Engineering | H10: All | I10: P0 | J10: 4 | K10: 1 | M10: You+Codex | N10: Backlog | O10: 4 | P10: =Settings!$B$4+O10 -> 46060 | Q10: =P10+ROUNDUP(K10,0)-1 -> 46060 | S10: Project opens; folders reflect architecture; autoload stubs.
A11: T-0010 | B11: Setup | C11: Tooling | D11: Configure code formatting & linting | E11: Adopt GDScript style guidelines; pre-commit hooks optional. | F11: 1 - Project Setup & Tooling | G11: DevOps | H11: All | I11: P1 | J11: 4 | K11: 1 | M11: You+Codex | N11: Backlog | O11: 5 | P11: =Settings!$B$4+O11 -> 46061 | Q11: =P11+ROUNDUP(K11,0)-1 -> 46061 | S11: Formatter/linter runs; CI step (if used) passes.
A12: T-0011 | B12: Setup | C12: Build | D12: Android export setup + keystore placeholders | E12: Configure Android export template, input, orientation landscape, signing placeholders. | F12: 1 - Project Setup & Tooling | G12: DevOps | H12: Android | I12: P0 | J12: 6 | K12: 1 | M12: You+Codex | N12: Backlog | O12: 5 | P12: =Settings!$B$4+O12 -> 46061 | Q12: =P12+ROUNDUP(K12,0)-1 -> 46061 | S12: Can export and run a blank build on Android device/emulator.
A13: T-0012 | B13: Setup | C13: Build | D13: PC export presets | E13: Configure Windows/Linux export presets and basic packaging. | F13: 1 - Project Setup & Tooling | G13: DevOps | H13: PC | I13: P1 | J13: 3 | K13: 0.5 | M13: You+Codex | N13: Backlog | O13: 5 | P13: =Settings!$B$4+O13 -> 46061 | Q13: =P13+ROUNDUP(K13,0)-1 -> 46061 | S13: Can export and run on PC.
A14: T-0013 | B14: Setup | C14: Infra | D14: Logging + debug overlay | E14: Add logging utility and optional on-screen debug panel for state, network, FPS. | F14: 1 - Project Setup & Tooling | G14: Engineering | H14: All | I14: P1 | J14: 6 | K14: 1 | M14: You+Codex | N14: Backlog | O14: 6 | P14: =Settings!$B$4+O14 -> 46062 | Q14: =P14+ROUNDUP(K14,0)-1 -> 46062 | S14: Logs written; debug overlay toggles via key/gesture.
A15: T-0014 | B15: Setup | C15: QA | D15: Lightweight test harness scaffolding | E15: Create test scene/scripts to run pure rules tests quickly. | F15: 1 - Project Setup & Tooling | G15: QA | H15: All | I15: P1 | J15: 6 | K15: 1 | M15: You+Codex | N15: Backlog | O15: 6 | P15: =Settings!$B$4+O15 -> 46062 | Q15: =P15+ROUNDUP(K15,0)-1 -> 46062 | S15: Can run tests headless or via scene; produces pass/fail output.
A16: T-0015 | B16: Engine | C16: Rules | D16: Implement Tile model + constants | E16: Tile representation: color, number, okey, fake okey; helpers for equality/serialization. | F16: 2 - Core Game Engine (Rules/State) | G16: Engineering | H16: All | I16: P0 | J16: 4 | K16: 1 | L16: T-0003 | M16: You+Codex | N16: Backlog | O16: 7 | P16: =Settings!$B$4+O16 -> 46063 | Q16: =P16+ROUNDUP(K16,0)-1 -> 46063 | S16: Tiles serialize/deserialize; unit tests for identity.
A17: T-0016 | B17: Engine | C17: Rules | D17: Implement deck generation + shuffle by seed | E17: Create full tile set; shuffle deterministically via seed; expose seed in GameState. | F17: 2 - Core Game Engine (Rules/State) | G17: Engineering | H17: All | I17: P0 | J17: 6 | K17: 1 | L17: T-0003 | M17: You+Codex | N17: Backlog | O17: 7 | P17: =Settings!$B$4+O17 -> 46063 | Q17: =P17+ROUNDUP(K17,0)-1 -> 46063 | S17: Given same seed, deck order identical across runs.
A18: T-0017 | B18: Engine | C18: Rules | D18: Implement dealing logic | E18: Deal initial hands according to TR rules (including extra tile to starting player). | F18: 2 - Core Game Engine (Rules/State) | G18: Engineering | H18: All | I18: P0 | J18: 6 | K18: 1 | L18: T-0001, T-0003, T-0010 | M18: You+Codex | N18: Backlog | O18: 8 | P18: =Settings!$B$4+O18 -> 46064 | Q18: =P18+ROUNDUP(K18,0)-1 -> 46064 | S18: Hands sizes correct; indicator set; discard initialized.
A19: T-0018 | B19: Engine | C19: State | D19: Define GameState + PlayerState classes | E19: Implement pure data objects and cloning/copy utilities. | F19: 2 - Core Game Engine (Rules/State) | G19: Engineering | H19: All | I19: P0 | J19: 6 | K19: 1 | L19: T-0003 | M19: You+Codex | N19: Backlog | O19: 8 | P19: =Settings!$B$4+O19 -> 46064 | Q19: =P19+ROUNDUP(K19,0)-1 -> 46064 | S19: State can deep-copy; no shared references.
A20: T-0019 | B20: Engine | C20: Actions | D20: Implement action validation framework | E20: validate_action(state, player, action, rules) returns ok + reason code. | F20: 2 - Core Game Engine (Rules/State) | G20: Engineering | H20: All | I20: P0 | J20: 10 | K20: 2 | L20: T-0003, T-0011 | M20: You+Codex | N20: Backlog | O20: 9 | P20: =Settings!$B$4+O20 -> 46065 | Q20: =P20+ROUNDUP(K20,0)-1 -> 46066 | S20: Every action returns deterministic result; reasons enumerated.
A21: T-0020 | B21: Engine | C21: Actions | D21: Implement apply_action reducer + event log | E21: apply_action returns new_state + delta/events (for UI + network). | F21: 2 - Core Game Engine (Rules/State) | G21: Engineering | H21: All | I21: P0 | J21: 10 | K21: 2 | L21: T-0016 | M21: You+Codex | N21: Backlog | O21: 10 | P21: =Settings!$B$4+O21 -> 46066 | Q21: =P21+ROUNDUP(K21,0)-1 -> 46067 | S21: Reducer is pure; events sufficient to animate UI.
A22: T-0021 | B22: Engine | C22: Rules | D22: Implement scoring engine | E22: Compute points for open melds, penalties, end-of-round scoring; support match targets. | F22: 2 - Core Game Engine (Rules/State) | G22: Engineering | H22: All | I22: P0 | J22: 12 | K22: 3 | L22: T-0001, T-0002, T-0017 | M22: You+Codex | N22: Backlog | O22: 11 | P22: =Settings!$B$4+O22 -> 46067 | Q22: =P22+ROUNDUP(K22,0)-1 -> 46069 | S22: Score matches spec; unit tests for sample rounds.
A23: T-0022 | B23: Engine | C23: Rules | D23: Implement RuleConfig + presets + hashing | E23: RuleConfig object with preset id + overrides; stable hash for online lobby. | F23: 2 - Core Game Engine (Rules/State) | G23: Engineering | H23: All | I23: P0 | J23: 8 | K23: 1.5 | L23: T-0002 | M23: You+Codex | N23: Backlog | O23: 10 | P23: =Settings!$B$4+O23 -> 46066 | Q23: =P23+ROUNDUP(K23,0)-1 -> 46067 | S23: Config serializes; hash stable; presets load.
A24: T-0023 | B24: Engine | C24: Serialization | D24: State snapshot + delta serialization | E24: Serialize GameState and delta/events to JSON or packed bytes for network/resync. | F24: 2 - Core Game Engine (Rules/State) | G24: Engineering | H24: Online | I24: P0 | J24: 10 | K24: 2 | L24: T-0014, T-0017 | M24: You+Codex | N24: Backlog | O24: 12 | P24: =Settings!$B$4+O24 -> 46068 | Q24: =P24+ROUNDUP(K24,0)-1 -> 46069 | S24: Snapshot round-trips; delta apply works.
A25: T-0024 | B25: Engine | C25: Undo | D25: Undo stack for offline | E25: Store prior snapshots or action log; allow undo to previous player-turn boundary. | F25: 2 - Core Game Engine (Rules/State) | G25: Engineering | H25: Offline | I25: P1 | J25: 8 | K25: 2 | L25: T-0017, T-0019 | M25: You+Codex | N25: Backlog | O25: 13 | P25: =Settings!$B$4+O25 -> 46069 | Q25: =P25+ROUNDUP(K25,0)-1 -> 46070 | S25: Undo restores exact state; limited by settings.
A26: T-0025 | B26: Engine | C26: Draw | D26: Implement draw-from-deck action | E26: Draw action updates hand and deck; events for animation. | F26: 2 - Core Game Engine (Rules/State) | G26: Engineering | H26: All | I26: P0 | J26: 6 | K26: 1 | L26: T-0016, T-0017, T-0018 | M26: You+Codex | N26: Backlog | O26: 14 | P26: =Settings!$B$4+O26 -> 46070 | Q26: =P26+ROUNDUP(K26,0)-1 -> 46070 | S26: Action validated; reducer updates state; tests cover edge cases.
A27: T-0026 | B27: Engine | C27: Draw | D27: Implement draw-from-discard action | E27: Draw discard respects rule config; updates discard pile. | F27: 2 - Core Game Engine (Rules/State) | G27: Engineering | H27: All | I27: P1 | J27: 6 | K27: 1 | L27: T-0016, T-0017, T-0018 | M27: You+Codex | N27: Backlog | O27: 14 | P27: =Settings!$B$4+O27 -> 46070 | Q27: =P27+ROUNDUP(K27,0)-1 -> 46070 | S27: Action validated; reducer updates state; tests cover edge cases.
... A38: T-0037 | B38: Offline | C38: Undo | D38: Undo button + rules (offline only) | E38: UI + controller integration for undo; block undo after info-revealing steps if needed. | F38: 3 - Offline Gameplay Loop | G38: Engineering | H38: Offline | I38: P1 | J38: 6 | K38: 1 | L38: T-0020 | M38: You+Codex | N38: Backlog | O38: 21 | P38: =Settings!$B$4+O38 -> 46077 | Q38: =P38+ROUNDUP(K38,0)-1 -> 46077 | S38: Undo works and is disabled appropriately.
A39: T-0038 | B39: Offline | C39: Persistence | D39: Settings persistence | E39: Save user settings: sound, accessibility, tips shown, last rules preset. | F39: 3 - Offline Gameplay Loop | G39: Engineering | H39: All | I39: P1 | J39: 4 | K39: 1 | M39: You+Codex | N39: Backlog | O39: 20 | P39: =Settings!$B$4+O39 -> 46076 | Q39: =P39+ROUNDUP(K39,0)-1 -> 46076 | S39: Settings persist between sessions.
A40: T-0039 | B40: Offline | C40: Tips | D40: First-game onboarding tips overlay (skippable) | E40: Guided overlay explaining draw/discard/meld/open; can skip; never forced again. | F40: 3 - Offline Gameplay Loop | G40: Engineering | H40: All | I40: P1 | J40: 8 | K40: 2 | L40: T-0005, T-0033 | M40: You+Codex | N40: Backlog | O40: 21 | P40: =Settings!$B$4+O40 -> 46077 | Q40: =P40+ROUNDUP(K40,0)-1 -> 46078 | S40: Tips show once; can be skipped; respects minimal verbosity later.
A41: T-0040 | B41: UI | C41: Framework | D41: Implement UI event bus & state-to-UI binding | E41: Listen to GameState events/deltas; update UI declaratively; avoid logic in view. | F41: 4 - UI/UX & Input | G41: Engineering | H41: All | I41: P0 | J41: 10 | K41: 2 | L41: T-0017 | M41: You+Codex | N41: Backlog | O41: 18 | P41: =Settings!$B$4+O41 -> 46074 | Q41: =P41+ROUNDUP(K41,0)-1 -> 46075 | S41: UI updates driven by events; minimal direct state mutation.
A42: T-0041 | B42: UI | C42: Table | D42: Game table layout (landscape) | E42: Create table scene with areas: player hand, meld area, deck/discard, opponent panels. | F42: 4 - UI/UX & Input | G42: Engineering | H42: All | I42: P0 | J42: 12 | K42: 3 | L42: T-0030 | M42: You+Codex | N42: Backlog | O42: 19 | P42: =Settings!$B$4+O42 -> 46075 | Q42: =P42+ROUNDUP(K42,0)-1 -> 46077 | S42: Table scales to multiple resolutions; safe margins.
A43: T-0042 | B43: UI | C43: Tiles | D43: Tile visual component | E43: Crisp flat tile art placeholder + numbers/colors; selection states; disabled state. | F43: 4 - UI/UX & Input | G43: Art | H43: All | I43: P0 | J43: 8 | K43: 2 | L43: T-0006 | M43: You+Codex | N43: Backlog | O43: 18 | P43: =Settings!$B$4+O43 -> 46074 | Q43: =P43+ROUNDUP(K43,0)-1 -> 46075 | S43: Tile style consistent; readable on mobile.
A44: T-0043 | B44: UI | C44: Input | D44: Tap-select interaction (baseline) | E44: Tap tile to select; buttons to meld/discard; long-press to inspect. | F44: 4 - UI/UX & Input | G44: Engineering | H44: All | I44: P0 | J44: 10 | K44: 2 | L44: T-0032, T-0031 | M44: You+Codex | N44: Backlog | O44: 20 | P44: =Settings!$B$4+O44 -> 46076 | Q44: =P44+ROUNDUP(K44,0)-1 -> 46077 | S44: All core actions can be performed without drag.
A45: T-0044 | B45: UI | C45: Input | D45: Drag & drop interaction (optional) | E45: Support dragging tiles to meld area/discard; fallback to tap-select always works. | F45: 4 - UI/UX & Input | G45: Engineering | H45: All | I45: P1 | J45: 12 | K45: 3 | L45: T-0033 | M45: You+Codex | N45: Backlog | O45: 23 | P45: =Settings!$B$4+O45 -> 46079 | Q45: =P45+ROUNDUP(K45,0)-1 -> 46081 | S45: Drag works on PC and touch; no accidental drops.
A46: T-0045 | B46: UI | C46: HUD | D46: Action buttons + turn/timer display | E46: Buttons: Draw, Meld/Open, Discard, End Round; show whose turn; timer slider support. | F46: 4 - UI/UX & Input | G46: Engineering | H46: All | I46: P0 | J46: 8 | K46: 2 | L46: T-0030, T-0015 | M46: You+Codex | N46: Backlog | O46: 20 | P46: =Settings!$B$4+O46 -> 46076 | Q46: =P46+ROUNDUP(K46,0)-1 -> 46077 | S46: Buttons enable/disable correctly by phase and authority.
A47: T-0046 | B47: UI | C47: Feedback | D47: Toast + error display with verbosity setting | E47: Minimal illegal toast; optional 'Why?' expansion; onboarding overrides verbosity. | F47: 4 - UI/UX & Input | G47: Engineering | H47: All | I47: P1 | J47: 8 | K47: 2 | L47: T-0027, T-0040 | M47: You+Codex | N47: Backlog | O47: 22 | P47: =Settings!$B$4+O47 -> 46078 | Q47: =P47+ROUNDUP(K47,0)-1 -> 46079 | S47: Errors are understandable; can be minimal for experienced play.
A48: T-0047 | B48: UI | C48: Animations | D48: Animation system (skippable) | E48: Animate draw/discard/meld; allow tap to skip/fast-forward; keep game snappy. | F48: 4 - UI/UX & Input | G48: Engineering | H48: All | I48: P1 | J48: 12 | K48: 3 | L48: T-0017, T-0031 | M48: You+Codex | N48: Backlog | O48: 24 | P48: =Settings!$B$4+O48 -> 46080 | Q48: =P48+ROUNDUP(K48,0)-1 -> 46082 | S48: Animations never block input; skip works; feels 'Balatro snappy'.
A49: T-0048 | B49: UI | C49: Menus | D49: Main menu + navigation | E49: Main menu: Offline, Online, Settings, Credits; simple transitions. | F49: 4 - UI/UX & Input | G49: Engineering | H49: All | I49: P0 | J49: 6 | K49: 1.5 | M49: You+Codex | N49: Backlog | O49: 18 | P49: =Settings!$B$4+O49 -> 46074 | Q49: =P49+ROUNDUP(K49,0)-1 -> 46075 | S49: All screens reachable; back navigation works on Android.
A50: T-0049 | B50: UI | C50: Menus | D50: Settings screen | E50: Settings: sound, music, tips verbosity, accessibility options, animation speed. | F50: 4 - UI/UX & Input | G50: Engineering | H50: All | I50: P1 | J50: 8 | K50: 2 | L50: T-0029 | M50: You+Codex | N50: Backlog | O50: 22 | P50: =Settings!$B$4+O50 -> 46078 | Q50: =P50+ROUNDUP(K50,0)-1 -> 46079 | S50: Settings apply immediately and persist.
...

Sheet Stage Plan
A1: Stage | B1: Stage Start | C1: Stage End | D1: Start Offset (d) | E1: Duration (d)
A2: 0 - Preproduction (Spec & Design Lock) | B2: 46056 | C2: 46059 | D2: 0 | E2: 4
A3: 1 - Project Setup & Tooling | B3: 46060 | C3: 46062 | D3: 4 | E3: 3
A4: 2 - Core Game Engine (Rules/State) | B4: 46063 | C4: 46074 | D4: 7 | E4: 12
A5: 3 - Offline Gameplay Loop | B5: 46074 | C5: 46078 | D5: 18 | E5: 5
A6: 4 - UI/UX & Input | B6: 46074 | C6: 46082 | D6: 18 | E6: 9
A7: 5 - Bots (AI) | B7: 46078 | C7: 46085 | D7: 22 | E7: 8
A8: 6 - Online Multiplayer (EOS + P2P) | B8: 46080 | C8: 46088 | D8: 24 | E8: 9
A9: 8 - Polish (Audio/Accessibility/Perf) | B9: 46086 | C9: 46091 | D9: 30 | E9: 6
A10: 7 - Reconnect & Resilience | B10: 46088 | C10: 46092 | D10: 32 | E10: 5
A11: 9 - QA & Test Matrix | B11: 46090 | C11: 46094 | D11: 34 | E11: 5
A12: 10 - Builds & Release Pipeline | B12: 46094 | C12: 46096 | D12: 38 | E12: 3
A13: 11 - Store/Distribution Prep | B13: 46096 | C13: 46098 | D13: 40 | E13: 3

Sheet Gantt
A1: Stage Gantt (based on Start Offset + Duration)
A2: Stage | B2: Start Offset (d) | C2: Duration (d)
A3: ='Stage Plan'!A2 -> 0 - Preproduction (Spec & Design Lock) | B3: ='Stage Plan'!D2 -> 0 | C3: ='Stage Plan'!E2 -> 4
A4: ='Stage Plan'!A3 -> 1 - Project Setup & Tooling | B4: ='Stage Plan'!D3 -> 4 | C4: ='Stage Plan'!E3 -> 3
A5: ='Stage Plan'!A4 -> 2 - Core Game Engine (Rules/State) | B5: ='Stage Plan'!D4 -> 7 | C5: ='Stage Plan'!E4 -> 12
A6: ='Stage Plan'!A5 -> 3 - Offline Gameplay Loop | B6: ='Stage Plan'!D5 -> 18 | C6: ='Stage Plan'!E5 -> 5
A7: ='Stage Plan'!A6 -> 4 - UI/UX & Input | B7: ='Stage Plan'!D6 -> 18 | C7: ='Stage Plan'!E6 -> 9
A8: ='Stage Plan'!A7 -> 5 - Bots (AI) | B8: ='Stage Plan'!D7 -> 22 | C8: ='Stage Plan'!E7 -> 8
A9: ='Stage Plan'!A8 -> 6 - Online Multiplayer (EOS + P2P) | B9: ='Stage Plan'!D8 -> 24 | C9: ='Stage Plan'!E8 -> 9
A10: ='Stage Plan'!A9 -> 8 - Polish (Audio/Accessibility/Perf) | B10: ='Stage Plan'!D9 -> 30 | C10: ='Stage Plan'!E9 -> 6
A11: ='Stage Plan'!A10 -> 7 - Reconnect & Resilience | B11: ='Stage Plan'!D10 -> 32 | C11: ='Stage Plan'!E10 -> 5
A12: ='Stage Plan'!A11 -> 9 - QA & Test Matrix | B12: ='Stage Plan'!D11 -> 34 | C12: ='Stage Plan'!E11 -> 5
A13: ='Stage Plan'!A12 -> 10 - Builds & Release Pipeline | B13: ='Stage Plan'!D12 -> 38 | C13: ='Stage Plan'!E12 -> 3
A14: ='Stage Plan'!A13 -> 11 - Store/Distribution Prep | B14: ='Stage Plan'!D13 -> 40 | C14: ='Stage Plan'!E13 -> 3

Sheet Dashboard
A1: Dashboard
A3: Tasks by Status
A4: Status | B4: Count
A5: Backlog | B5: =COUNTIF(Tasks!$N$2:$N$94,"Backlog") -> 93
A6: Planned | B6: =COUNTIF(Tasks!$N$2:$N$94,"Planned") -> 0
A7: In Progress | B7: =COUNTIF(Tasks!$N$2:$N$94,"In Progress") -> 0
A8: Blocked | B8: =COUNTIF(Tasks!$N$2:$N$94,"Blocked") -> 0
A9: Review | B9: =COUNTIF(Tasks!$N$2:$N$94,"Review") -> 0
A10: Done | B10: =COUNTIF(Tasks!$N$2:$N$94,"Done") -> 0
A14: Tasks by Stage
A15: Stage | B15: Count
A16: 0 - Preproduction (Spec & Design Lock) | B16: =COUNTIF(Tasks!$F$2:$F$94,A16) -> 7
A17: 1 - Project Setup & Tooling | B17: =COUNTIF(Tasks!$F$2:$F$94,A17) -> 7
A18: 2 - Core Game Engine (Rules/State) | B18: =COUNTIF(Tasks!$F$2:$F$94,A18) -> 20
A19: 3 - Offline Gameplay Loop | B19: =COUNTIF(Tasks!$F$2:$F$94,A19) -> 5
A20: 4 - UI/UX & Input | B20: =COUNTIF(Tasks!$F$2:$F$94,A20) -> 11
A21: 5 - Bots (AI) | B21: =COUNTIF(Tasks!$F$2:$F$94,A21) -> 7
A22: 6 - Online Multiplayer (EOS + P2P) | B22: =COUNTIF(Tasks!$F$2:$F$94,A22) -> 9
A23: 7 - Reconnect & Resilience | B23: =COUNTIF(Tasks!$F$2:$F$94,A23) -> 5
A24: 8 - Polish (Audio/Accessibility/Perf) | B24: =COUNTIF(Tasks!$F$2:$F$94,A24) -> 7
A25: 9 - QA & Test Matrix | B25: =COUNTIF(Tasks!$F$2:$F$94,A25) -> 5
A26: 10 - Builds & Release Pipeline | B26: =COUNTIF(Tasks!$F$2:$F$94,A26) -> 5
A27: 11 - Store/Distribution Prep | B27: =COUNTIF(Tasks!$F$2:$F$94,A27) -> 5
